The following values were not passed to `accelerate launch` and had defaults used instead:
	`--num_processes` was set to a value of `1`
	`--num_machines` was set to a value of `1`
	`--mixed_precision` was set to a value of `'no'`
	`--dynamo_backend` was set to a value of `'no'`
To avoid this warning pass in values for each of the problematic parameters or run `accelerate config`.
/workspace/llada-poe/.venv/bin/python3: can't open file '/workspace/llada-poe/llada/eval_llada.py': [Errno 2] No such file or directory
Traceback (most recent call last):
  File "/workspace/llada-poe/.venv/bin/accelerate", line 10, in <module>
    sys.exit(main())
             ^^^^^^
  File "/workspace/llada-poe/.venv/lib/python3.12/site-packages/accelerate/commands/accelerate_cli.py", line 50, in main
    args.func(args)
  File "/workspace/llada-poe/.venv/lib/python3.12/site-packages/accelerate/commands/launch.py", line 1235, in launch_command
    simple_launcher(args)
  File "/workspace/llada-poe/.venv/lib/python3.12/site-packages/accelerate/commands/launch.py", line 823, in simple_launcher
    raise subprocess.CalledProcessError(returncode=process.returncode, cmd=cmd)
subprocess.CalledProcessError: Command '['/workspace/llada-poe/.venv/bin/python3', 'llada/eval_llada.py', '--tasks', 'mbpp', '--num_fewshot', '3', '--confirm_run_unsafe_code', '--model', 'llada_dist', '--model_args', 'model_path=GSAI-ML/LLaDA-1.5,gen_length=128,steps=4,block_length=32,use_cache=True,dual_cache=True,threshold=0.9,show_speed=True', '--output_path', 'test_results/llada15_mbpp_128', '--log_samples']' returned non-zero exit status 2.
